[2025-07-29 05:54:33.618] [ERROR   ] [PID:2855939-TID:140508872271680] [language_ops.database:217] [FUNC:log_database_operation] DB_SELECT_FAILED: UserProfile for user 386787633 fields=['language'] - None
[2025-07-29 05:54:33.621] [ERROR   ] [PID:2855939-TID:140508872271680] [language_ops.database:217] [FUNC:log_database_operation] DB_SELECT_FAILED: UserProfile for user 386787633 fields=['language'] - no such column: accounts_userprofile.latitude
[2025-07-29 05:54:33.622] [ERROR   ] [PID:2855939-TID:140508872271680] [language_ops.emergency_bot.telegram_bot.language_bridge:83] [FUNC:get_user_language_async] Error getting user language for 386787633: no such column: accounts_userprofile.latitude
Traceback (most recent call last):
  File "/home/hdmsofob/virtualenv/gaddisa/3.12/lib/python3.12/site-packages/django/db/backends/utils.py", line 105, in _execute
    return self.cursor.execute(sql, params)
           ^^^^^^^^^^^^^^^^^^^^^^^^^^^^^^^^
  File "/home/hdmsofob/virtualenv/gaddisa/3.12/lib/python3.12/site-packages/django/db/backends/sqlite3/base.py", line 360, in execute
    return super().execute(query, params)
           ^^^^^^^^^^^^^^^^^^^^^^^^^^^^^^
sqlite3.OperationalError: no such column: accounts_userprofile.latitude

The above exception was the direct cause of the following exception:

Traceback (most recent call last):
  File "/home/hdmsofob/gaddisa/emergency_bot/telegram_bot/language_bridge.py", line 71, in get_user_language_async
    language = await sync_to_async(get_user_language)(user_id_str)
               ^^^^^^^^^^^^^^^^^^^^^^^^^^^^^^^^^^^^^^^^^^^^^^^^^^^
  File "/home/hdmsofob/virtualenv/gaddisa/3.12/lib/python3.12/site-packages/asgiref/sync.py", line 468, in __call__
    ret = await asyncio.shield(exec_coro)
          ^^^^^^^^^^^^^^^^^^^^^^^^^^^^^^^
  File "/opt/alt/python312/lib64/python3.12/concurrent/futures/thread.py", line 59, in run
    result = self.fn(*self.args, **self.kwargs)
             ^^^^^^^^^^^^^^^^^^^^^^^^^^^^^^^^^^
  File "/home/hdmsofob/virtualenv/gaddisa/3.12/lib/python3.12/site-packages/asgiref/sync.py", line 522, in thread_handler
    return func(*args, **kwargs)
           ^^^^^^^^^^^^^^^^^^^^^
  File "/home/hdmsofob/gaddisa/emergency_bot/utils/translations.py", line 126, in get_user_language
    user = UserProfile.objects.get(telegram_id=telegram_id)
           ^^^^^^^^^^^^^^^^^^^^^^^^^^^^^^^^^^^^^^^^^^^^^^^^
  File "/home/hdmsofob/virtualenv/gaddisa/3.12/lib/python3.12/site-packages/django/db/models/manager.py", line 87, in manager_method
    return getattr(self.get_queryset(), name)(*args, **kwargs)
           ^^^^^^^^^^^^^^^^^^^^^^^^^^^^^^^^^^^^^^^^^^^^^^^^^^^
  File "/home/hdmsofob/virtualenv/gaddisa/3.12/lib/python3.12/site-packages/django/db/models/query.py", line 629, in get
    num = len(clone)
          ^^^^^^^^^^
  File "/home/hdmsofob/virtualenv/gaddisa/3.12/lib/python3.12/site-packages/django/db/models/query.py", line 366, in __len__
    self._fetch_all()
  File "/home/hdmsofob/virtualenv/gaddisa/3.12/lib/python3.12/site-packages/django/db/models/query.py", line 1935, in _fetch_all
    self._result_cache = list(self._iterable_class(self))
                         ^^^^^^^^^^^^^^^^^^^^^^^^^^^^^^^^
  File "/home/hdmsofob/virtualenv/gaddisa/3.12/lib/python3.12/site-packages/django/db/models/query.py", line 91, in __iter__
    results = compiler.execute_sql(
              ^^^^^^^^^^^^^^^^^^^^^
  File "/home/hdmsofob/virtualenv/gaddisa/3.12/lib/python3.12/site-packages/django/db/models/sql/compiler.py", line 1622, in execute_sql
    cursor.execute(sql, params)
  File "/home/hdmsofob/virtualenv/gaddisa/3.12/lib/python3.12/site-packages/django/db/backends/utils.py", line 122, in execute
    return super().execute(sql, params)
           ^^^^^^^^^^^^^^^^^^^^^^^^^^^^
  File "/home/hdmsofob/virtualenv/gaddisa/3.12/lib/python3.12/site-packages/django/db/backends/utils.py", line 79, in execute
    return self._execute_with_wrappers(
           ^^^^^^^^^^^^^^^^^^^^^^^^^^^^
  File "/home/hdmsofob/virtualenv/gaddisa/3.12/lib/python3.12/site-packages/django/db/backends/utils.py", line 92, in _execute_with_wrappers
    return executor(sql, params, many, context)
           ^^^^^^^^^^^^^^^^^^^^^^^^^^^^^^^^^^^^
  File "/home/hdmsofob/virtualenv/gaddisa/3.12/lib/python3.12/site-packages/django/db/backends/utils.py", line 100, in _execute
    with self.db.wrap_database_errors:
         ^^^^^^^^^^^^^^^^^^^^^^^^^^^^
  File "/home/hdmsofob/virtualenv/gaddisa/3.12/lib/python3.12/site-packages/django/db/utils.py", line 91, in __exit__
    raise dj_exc_value.with_traceback(traceback) from exc_value
  File "/home/hdmsofob/virtualenv/gaddisa/3.12/lib/python3.12/site-packages/django/db/backends/utils.py", line 105, in _execute
    return self.cursor.execute(sql, params)
           ^^^^^^^^^^^^^^^^^^^^^^^^^^^^^^^^
  File "/home/hdmsofob/virtualenv/gaddisa/3.12/lib/python3.12/site-packages/django/db/backends/sqlite3/base.py", line 360, in execute
    return super().execute(query, params)
           ^^^^^^^^^^^^^^^^^^^^^^^^^^^^^^
django.db.utils.OperationalError: no such column: accounts_userprofile.latitude
[2025-07-29 06:21:53.879] [ERROR   ] [PID:2998690-TID:140190523901760] [language_ops.database:217] [FUNC:log_database_operation] DB_SELECT_FAILED: UserProfile for user 386787633 fields=['language'] - None
[2025-07-29 06:21:53.883] [ERROR   ] [PID:2998690-TID:140190523901760] [language_ops.database:217] [FUNC:log_database_operation] DB_SELECT_FAILED: UserProfile for user 386787633 fields=['language'] - no such column: accounts_userprofile.latitude
[2025-07-29 06:21:53.886] [ERROR   ] [PID:2998690-TID:140190523901760] [language_ops.emergency_bot.telegram_bot.language_bridge:83] [FUNC:get_user_language_async] Error getting user language for 386787633: no such column: accounts_userprofile.latitude
Traceback (most recent call last):
  File "/home/hdmsofob/virtualenv/gaddisa/3.12/lib/python3.12/site-packages/django/db/backends/utils.py", line 105, in _execute
    return self.cursor.execute(sql, params)
           ^^^^^^^^^^^^^^^^^^^^^^^^^^^^^^^^
  File "/home/hdmsofob/virtualenv/gaddisa/3.12/lib/python3.12/site-packages/django/db/backends/sqlite3/base.py", line 360, in execute
    return super().execute(query, params)
           ^^^^^^^^^^^^^^^^^^^^^^^^^^^^^^
sqlite3.OperationalError: no such column: accounts_userprofile.latitude

The above exception was the direct cause of the following exception:

Traceback (most recent call last):
  File "/home/hdmsofob/gaddisa/emergency_bot/telegram_bot/language_bridge.py", line 71, in get_user_language_async
    language = await sync_to_async(get_user_language)(user_id_str)
               ^^^^^^^^^^^^^^^^^^^^^^^^^^^^^^^^^^^^^^^^^^^^^^^^^^^
  File "/home/hdmsofob/virtualenv/gaddisa/3.12/lib/python3.12/site-packages/asgiref/sync.py", line 468, in __call__
    ret = await asyncio.shield(exec_coro)
          ^^^^^^^^^^^^^^^^^^^^^^^^^^^^^^^
  File "/opt/alt/python312/lib64/python3.12/concurrent/futures/thread.py", line 59, in run
    result = self.fn(*self.args, **self.kwargs)
             ^^^^^^^^^^^^^^^^^^^^^^^^^^^^^^^^^^
  File "/home/hdmsofob/virtualenv/gaddisa/3.12/lib/python3.12/site-packages/asgiref/sync.py", line 522, in thread_handler
    return func(*args, **kwargs)
           ^^^^^^^^^^^^^^^^^^^^^
  File "/home/hdmsofob/gaddisa/emergency_bot/utils/translations.py", line 126, in get_user_language
    user = UserProfile.objects.get(telegram_id=telegram_id)
           ^^^^^^^^^^^^^^^^^^^^^^^^^^^^^^^^^^^^^^^^^^^^^^^^
  File "/home/hdmsofob/virtualenv/gaddisa/3.12/lib/python3.12/site-packages/django/db/models/manager.py", line 87, in manager_method
    return getattr(self.get_queryset(), name)(*args, **kwargs)
           ^^^^^^^^^^^^^^^^^^^^^^^^^^^^^^^^^^^^^^^^^^^^^^^^^^^
  File "/home/hdmsofob/virtualenv/gaddisa/3.12/lib/python3.12/site-packages/django/db/models/query.py", line 629, in get
    num = len(clone)
          ^^^^^^^^^^
  File "/home/hdmsofob/virtualenv/gaddisa/3.12/lib/python3.12/site-packages/django/db/models/query.py", line 366, in __len__
    self._fetch_all()
  File "/home/hdmsofob/virtualenv/gaddisa/3.12/lib/python3.12/site-packages/django/db/models/query.py", line 1935, in _fetch_all
    self._result_cache = list(self._iterable_class(self))
                         ^^^^^^^^^^^^^^^^^^^^^^^^^^^^^^^^
  File "/home/hdmsofob/virtualenv/gaddisa/3.12/lib/python3.12/site-packages/django/db/models/query.py", line 91, in __iter__
    results = compiler.execute_sql(
              ^^^^^^^^^^^^^^^^^^^^^
  File "/home/hdmsofob/virtualenv/gaddisa/3.12/lib/python3.12/site-packages/django/db/models/sql/compiler.py", line 1622, in execute_sql
    cursor.execute(sql, params)
  File "/home/hdmsofob/virtualenv/gaddisa/3.12/lib/python3.12/site-packages/django/db/backends/utils.py", line 122, in execute
    return super().execute(sql, params)
           ^^^^^^^^^^^^^^^^^^^^^^^^^^^^
  File "/home/hdmsofob/virtualenv/gaddisa/3.12/lib/python3.12/site-packages/django/db/backends/utils.py", line 79, in execute
    return self._execute_with_wrappers(
           ^^^^^^^^^^^^^^^^^^^^^^^^^^^^
  File "/home/hdmsofob/virtualenv/gaddisa/3.12/lib/python3.12/site-packages/django/db/backends/utils.py", line 92, in _execute_with_wrappers
    return executor(sql, params, many, context)
           ^^^^^^^^^^^^^^^^^^^^^^^^^^^^^^^^^^^^
  File "/home/hdmsofob/virtualenv/gaddisa/3.12/lib/python3.12/site-packages/django/db/backends/utils.py", line 100, in _execute
    with self.db.wrap_database_errors:
         ^^^^^^^^^^^^^^^^^^^^^^^^^^^^
  File "/home/hdmsofob/virtualenv/gaddisa/3.12/lib/python3.12/site-packages/django/db/utils.py", line 91, in __exit__
    raise dj_exc_value.with_traceback(traceback) from exc_value
  File "/home/hdmsofob/virtualenv/gaddisa/3.12/lib/python3.12/site-packages/django/db/backends/utils.py", line 105, in _execute
    return self.cursor.execute(sql, params)
           ^^^^^^^^^^^^^^^^^^^^^^^^^^^^^^^^
  File "/home/hdmsofob/virtualenv/gaddisa/3.12/lib/python3.12/site-packages/django/db/backends/sqlite3/base.py", line 360, in execute
    return super().execute(query, params)
           ^^^^^^^^^^^^^^^^^^^^^^^^^^^^^^
django.db.utils.OperationalError: no such column: accounts_userprofile.latitude
[2025-07-29 06:21:53.887] [ERROR   ] [PID:2998690-TID:140190523901760] [language_ops.database:217] [FUNC:log_database_operation] DB_UPDATE_FAILED: UserProfile for user 386787633 fields=['language'] - None
[2025-07-29 06:21:53.888] [ERROR   ] [PID:2998690-TID:140190196508416] [language_ops.database:217] [FUNC:log_database_operation] DB_GET_OR_CREATE_FAILED: UserProfile for user 386787633 fields=['telegram_id', 'language'] - None
[2025-07-29 06:21:53.891] [ERROR   ] [PID:2998690-TID:140190196508416] [language_ops.emergency_bot.utils.translations:267] [FUNC:update_user_language] Error updating language for user 386787633: no such column: accounts_userprofile.latitude
Traceback (most recent call last):
  File "/home/hdmsofob/virtualenv/gaddisa/3.12/lib/python3.12/site-packages/django/db/backends/utils.py", line 105, in _execute
    return self.cursor.execute(sql, params)
           ^^^^^^^^^^^^^^^^^^^^^^^^^^^^^^^^
  File "/home/hdmsofob/virtualenv/gaddisa/3.12/lib/python3.12/site-packages/django/db/backends/sqlite3/base.py", line 360, in execute
    return super().execute(query, params)
           ^^^^^^^^^^^^^^^^^^^^^^^^^^^^^^
sqlite3.OperationalError: no such column: accounts_userprofile.latitude

The above exception was the direct cause of the following exception:

Traceback (most recent call last):
  File "/home/hdmsofob/gaddisa/emergency_bot/utils/translations.py", line 189, in update_user_language
    existing_user = UserProfile.objects.get(telegram_id=telegram_id)
                    ^^^^^^^^^^^^^^^^^^^^^^^^^^^^^^^^^^^^^^^^^^^^^^^^
  File "/home/hdmsofob/virtualenv/gaddisa/3.12/lib/python3.12/site-packages/django/db/models/manager.py", line 87, in manager_method
    return getattr(self.get_queryset(), name)(*args, **kwargs)
           ^^^^^^^^^^^^^^^^^^^^^^^^^^^^^^^^^^^^^^^^^^^^^^^^^^^
  File "/home/hdmsofob/virtualenv/gaddisa/3.12/lib/python3.12/site-packages/django/db/models/query.py", line 629, in get
    num = len(clone)
          ^^^^^^^^^^
  File "/home/hdmsofob/virtualenv/gaddisa/3.12/lib/python3.12/site-packages/django/db/models/query.py", line 366, in __len__
    self._fetch_all()
  File "/home/hdmsofob/virtualenv/gaddisa/3.12/lib/python3.12/site-packages/django/db/models/query.py", line 1935, in _fetch_all
    self._result_cache = list(self._iterable_class(self))
                         ^^^^^^^^^^^^^^^^^^^^^^^^^^^^^^^^
  File "/home/hdmsofob/virtualenv/gaddisa/3.12/lib/python3.12/site-packages/django/db/models/query.py", line 91, in __iter__
    results = compiler.execute_sql(
              ^^^^^^^^^^^^^^^^^^^^^
  File "/home/hdmsofob/virtualenv/gaddisa/3.12/lib/python3.12/site-packages/django/db/models/sql/compiler.py", line 1622, in execute_sql
    cursor.execute(sql, params)
  File "/home/hdmsofob/virtualenv/gaddisa/3.12/lib/python3.12/site-packages/django/db/backends/utils.py", line 122, in execute
    return super().execute(sql, params)
           ^^^^^^^^^^^^^^^^^^^^^^^^^^^^
  File "/home/hdmsofob/virtualenv/gaddisa/3.12/lib/python3.12/site-packages/django/db/backends/utils.py", line 79, in execute
    return self._execute_with_wrappers(
           ^^^^^^^^^^^^^^^^^^^^^^^^^^^^
  File "/home/hdmsofob/virtualenv/gaddisa/3.12/lib/python3.12/site-packages/django/db/backends/utils.py", line 92, in _execute_with_wrappers
    return executor(sql, params, many, context)
           ^^^^^^^^^^^^^^^^^^^^^^^^^^^^^^^^^^^^
  File "/home/hdmsofob/virtualenv/gaddisa/3.12/lib/python3.12/site-packages/django/db/backends/utils.py", line 100, in _execute
    with self.db.wrap_database_errors:
         ^^^^^^^^^^^^^^^^^^^^^^^^^^^^
  File "/home/hdmsofob/virtualenv/gaddisa/3.12/lib/python3.12/site-packages/django/db/utils.py", line 91, in __exit__
    raise dj_exc_value.with_traceback(traceback) from exc_value
  File "/home/hdmsofob/virtualenv/gaddisa/3.12/lib/python3.12/site-packages/django/db/backends/utils.py", line 105, in _execute
    return self.cursor.execute(sql, params)
           ^^^^^^^^^^^^^^^^^^^^^^^^^^^^^^^^
  File "/home/hdmsofob/virtualenv/gaddisa/3.12/lib/python3.12/site-packages/django/db/backends/sqlite3/base.py", line 360, in execute
    return super().execute(query, params)
           ^^^^^^^^^^^^^^^^^^^^^^^^^^^^^^
django.db.utils.OperationalError: no such column: accounts_userprofile.latitude
[2025-07-29 06:21:53.891] [ERROR   ] [PID:2998690-TID:140190196508416] [language_ops.database:217] [FUNC:log_database_operation] DB_UPDATE_FAILED: UserProfile for user 386787633 fields=['language'] - Exception in update_user_language: no such column: accounts_userprofile.latitude
[2025-07-29 06:21:53.891] [ERROR   ] [PID:2998690-TID:140190196508416] [language_ops.language_change:192] [FUNC:log_user_language_change] LANGUAGE_CHANGE_FAILED: User 386787633 failed to change from 'unknown' to 'am' - Exception in update_user_language: no such column: accounts_userprofile.latitude
[2025-07-29 06:21:53.893] [ERROR   ] [PID:2998690-TID:140190196508416] [language_ops.emergency_bot.utils.translations:274] [FUNC:update_user_language] Full traceback: Traceback (most recent call last):
  File "/home/hdmsofob/virtualenv/gaddisa/3.12/lib/python3.12/site-packages/django/db/backends/utils.py", line 105, in _execute
    return self.cursor.execute(sql, params)
           ^^^^^^^^^^^^^^^^^^^^^^^^^^^^^^^^
  File "/home/hdmsofob/virtualenv/gaddisa/3.12/lib/python3.12/site-packages/django/db/backends/sqlite3/base.py", line 360, in execute
    return super().execute(query, params)
           ^^^^^^^^^^^^^^^^^^^^^^^^^^^^^^
sqlite3.OperationalError: no such column: accounts_userprofile.latitude

The above exception was the direct cause of the following exception:

Traceback (most recent call last):
  File "/home/hdmsofob/gaddisa/emergency_bot/utils/translations.py", line 189, in update_user_language
    existing_user = UserProfile.objects.get(telegram_id=telegram_id)
                    ^^^^^^^^^^^^^^^^^^^^^^^^^^^^^^^^^^^^^^^^^^^^^^^^
  File "/home/hdmsofob/virtualenv/gaddisa/3.12/lib/python3.12/site-packages/django/db/models/manager.py", line 87, in manager_method
    return getattr(self.get_queryset(), name)(*args, **kwargs)
           ^^^^^^^^^^^^^^^^^^^^^^^^^^^^^^^^^^^^^^^^^^^^^^^^^^^
  File "/home/hdmsofob/virtualenv/gaddisa/3.12/lib/python3.12/site-packages/django/db/models/query.py", line 629, in get
    num = len(clone)
          ^^^^^^^^^^
  File "/home/hdmsofob/virtualenv/gaddisa/3.12/lib/python3.12/site-packages/django/db/models/query.py", line 366, in __len__
    self._fetch_all()
  File "/home/hdmsofob/virtualenv/gaddisa/3.12/lib/python3.12/site-packages/django/db/models/query.py", line 1935, in _fetch_all
    self._result_cache = list(self._iterable_class(self))
                         ^^^^^^^^^^^^^^^^^^^^^^^^^^^^^^^^
  File "/home/hdmsofob/virtualenv/gaddisa/3.12/lib/python3.12/site-packages/django/db/models/query.py", line 91, in __iter__
    results = compiler.execute_sql(
              ^^^^^^^^^^^^^^^^^^^^^
  File "/home/hdmsofob/virtualenv/gaddisa/3.12/lib/python3.12/site-packages/django/db/models/sql/compiler.py", line 1622, in execute_sql
    cursor.execute(sql, params)
  File "/home/hdmsofob/virtualenv/gaddisa/3.12/lib/python3.12/site-packages/django/db/backends/utils.py", line 122, in execute
    return super().execute(sql, params)
           ^^^^^^^^^^^^^^^^^^^^^^^^^^^^
  File "/home/hdmsofob/virtualenv/gaddisa/3.12/lib/python3.12/site-packages/django/db/backends/utils.py", line 79, in execute
    return self._execute_with_wrappers(
           ^^^^^^^^^^^^^^^^^^^^^^^^^^^^
  File "/home/hdmsofob/virtualenv/gaddisa/3.12/lib/python3.12/site-packages/django/db/backends/utils.py", line 92, in _execute_with_wrappers
    return executor(sql, params, many, context)
           ^^^^^^^^^^^^^^^^^^^^^^^^^^^^^^^^^^^^
  File "/home/hdmsofob/virtualenv/gaddisa/3.12/lib/python3.12/site-packages/django/db/backends/utils.py", line 100, in _execute
    with self.db.wrap_database_errors:
         ^^^^^^^^^^^^^^^^^^^^^^^^^^^^
  File "/home/hdmsofob/virtualenv/gaddisa/3.12/lib/python3.12/site-packages/django/db/utils.py", line 91, in __exit__
    raise dj_exc_value.with_traceback(traceback) from exc_value
  File "/home/hdmsofob/virtualenv/gaddisa/3.12/lib/python3.12/site-packages/django/db/backends/utils.py", line 105, in _execute
    return self.cursor.execute(sql, params)
           ^^^^^^^^^^^^^^^^^^^^^^^^^^^^^^^^
  File "/home/hdmsofob/virtualenv/gaddisa/3.12/lib/python3.12/site-packages/django/db/backends/sqlite3/base.py", line 360, in execute
    return super().execute(query, params)
           ^^^^^^^^^^^^^^^^^^^^^^^^^^^^^^
django.db.utils.OperationalError: no such column: accounts_userprofile.latitude

[2025-07-29 06:21:53.893] [ERROR   ] [PID:2998690-TID:140190523901760] [language_ops.database:217] [FUNC:log_database_operation] DB_UPDATE_FAILED: UserProfile for user 386787633 fields=['language'] - update_user_language returned False
[2025-07-29 06:21:53.893] [ERROR   ] [PID:2998690-TID:140190523901760] [language_ops.language_change:192] [FUNC:log_user_language_change] LANGUAGE_CHANGE_FAILED: User 386787633 failed to change from 'en' to 'am' - update_user_language returned False
[2025-07-29 06:21:53.894] [ERROR   ] [PID:2998690-TID:140190523901760] [language_ops.emergency_bot.telegram_bot.language_bridge:132] [FUNC:update_user_language_async] Failed to update language for user 386787633: update_user_language returned False
[2025-07-29 06:21:53.894] [ERROR   ] [PID:2998690-TID:140190523901760] [language_ops.emergency_bot.telegram_bot.language_bridge:282] [FUNC:language_button_callback] Language update failed for user 386787633, showing error message
[2025-07-30 23:45:37.059] [ERROR   ] [PID:1181727-TID:140384139224896] [language_ops.database:217] [FUNC:log_database_operation] DB_SELECT_FAILED: UserProfile for user 559773363 fields=['language'] - None
[2025-07-30 23:46:43.542] [ERROR   ] [PID:1181727-TID:140384139224896] [language_ops.database:217] [FUNC:log_database_operation] DB_SELECT_FAILED: UserProfile for user 559773363 fields=['language'] - None
[2025-07-30 23:46:44.751] [ERROR   ] [PID:1181727-TID:140384139224896] [language_ops.database:217] [FUNC:log_database_operation] DB_SELECT_FAILED: UserProfile for user 559773363 fields=['language'] - None
[2025-07-30 23:46:44.754] [ERROR   ] [PID:1181727-TID:140384139224896] [language_ops.database:217] [FUNC:log_database_operation] DB_UPDATE_FAILED: UserProfile for user 559773363 fields=['language'] - None
[2025-07-30 23:46:44.756] [ERROR   ] [PID:1181727-TID:140383811831552] [language_ops.database:217] [FUNC:log_database_operation] DB_GET_OR_CREATE_FAILED: UserProfile for user 559773363 fields=['telegram_id', 'language'] - None
[2025-07-30 23:46:44.758] [ERROR   ] [PID:1181727-TID:140383811831552] [language_ops.database:217] [FUNC:log_database_operation] DB_UPDATE_FAILED: UserProfile for user 559773363 fields=['language'] - None
[2025-07-30 23:46:52.453] [ERROR   ] [PID:1181727-TID:140384139224896] [language_ops.database:217] [FUNC:log_database_operation] DB_SELECT_FAILED: UserProfile for user 559773363 fields=['language'] - None
[2025-07-30 23:46:53.574] [ERROR   ] [PID:1181727-TID:140384139224896] [language_ops.database:217] [FUNC:log_database_operation] DB_SELECT_FAILED: UserProfile for user 559773363 fields=['language'] - None
[2025-07-30 23:46:53.576] [ERROR   ] [PID:1181727-TID:140384139224896] [language_ops.database:217] [FUNC:log_database_operation] DB_UPDATE_FAILED: UserProfile for user 559773363 fields=['language'] - None
[2025-07-30 23:46:53.577] [ERROR   ] [PID:1181727-TID:140383811831552] [language_ops.database:217] [FUNC:log_database_operation] DB_GET_OR_CREATE_FAILED: UserProfile for user 559773363 fields=['telegram_id', 'language'] - None
[2025-07-30 23:46:53.580] [ERROR   ] [PID:1181727-TID:140383811831552] [language_ops.database:217] [FUNC:log_database_operation] DB_UPDATE_FAILED: UserProfile for user 559773363 fields=['language'] - None
[2025-07-30 23:47:06.190] [ERROR   ] [PID:1181727-TID:140384139224896] [language_ops.database:217] [FUNC:log_database_operation] DB_SELECT_FAILED: UserProfile for user 559773363 fields=['language'] - None
[2025-07-30 23:47:08.047] [ERROR   ] [PID:1181727-TID:140384139224896] [language_ops.database:217] [FUNC:log_database_operation] DB_SELECT_FAILED: UserProfile for user 559773363 fields=['language'] - None
[2025-07-31 00:14:01.570] [ERROR   ] [PID:1299830-TID:140624003602240] [language_ops.database:217] [FUNC:log_database_operation] DB_SELECT_FAILED: UserProfile for user 1841727454 fields=['language'] - None
[2025-07-31 00:14:07.689] [ERROR   ] [PID:1299830-TID:140624003602240] [language_ops.database:217] [FUNC:log_database_operation] DB_SELECT_FAILED: UserProfile for user 1841727454 fields=['language'] - None
[2025-07-31 00:14:15.300] [ERROR   ] [PID:1299830-TID:140624003602240] [language_ops.database:217] [FUNC:log_database_operation] DB_SELECT_FAILED: UserProfile for user 1841727454 fields=['language'] - None
[2025-07-31 00:14:16.627] [ERROR   ] [PID:1299830-TID:140624003602240] [language_ops.database:217] [FUNC:log_database_operation] DB_SELECT_FAILED: UserProfile for user 1841727454 fields=['language'] - None
[2025-07-31 00:14:16.629] [ERROR   ] [PID:1299830-TID:140624003602240] [language_ops.database:217] [FUNC:log_database_operation] DB_UPDATE_FAILED: UserProfile for user 1841727454 fields=['language'] - None
[2025-07-31 00:14:16.631] [ERROR   ] [PID:1299830-TID:140623604610816] [language_ops.database:217] [FUNC:log_database_operation] DB_GET_OR_CREATE_FAILED: UserProfile for user 1841727454 fields=['telegram_id', 'language'] - None
[2025-07-31 00:14:16.633] [ERROR   ] [PID:1299830-TID:140623604610816] [language_ops.database:217] [FUNC:log_database_operation] DB_UPDATE_FAILED: UserProfile for user 1841727454 fields=['language'] - None
[2025-07-31 00:18:28.279] [ERROR   ] [PID:1316807-TID:140204632602432] [language_ops.database:217] [FUNC:log_database_operation] DB_SELECT_FAILED: UserProfile for user 1841727454 fields=['language'] - None
[2025-07-31 00:18:29.535] [ERROR   ] [PID:1316807-TID:140204632602432] [language_ops.database:217] [FUNC:log_database_operation] DB_SELECT_FAILED: UserProfile for user 1841727454 fields=['language'] - None
[2025-07-31 00:18:29.538] [ERROR   ] [PID:1316807-TID:140204632602432] [language_ops.database:217] [FUNC:log_database_operation] DB_UPDATE_FAILED: UserProfile for user 1841727454 fields=['language'] - None
[2025-07-31 00:18:29.540] [ERROR   ] [PID:1316807-TID:140204236998400] [language_ops.database:217] [FUNC:log_database_operation] DB_GET_OR_CREATE_FAILED: UserProfile for user 1841727454 fields=['telegram_id', 'language'] - None
[2025-07-31 00:18:29.542] [ERROR   ] [PID:1316807-TID:140204236998400] [language_ops.database:217] [FUNC:log_database_operation] DB_UPDATE_FAILED: UserProfile for user 1841727454 fields=['language'] - None
[2025-07-31 00:22:56.338] [ERROR   ] [PID:1316807-TID:140204632602432] [language_ops.database:217] [FUNC:log_database_operation] DB_SELECT_FAILED: UserProfile for user 559773363 fields=['language'] - None
[2025-07-31 00:22:57.510] [ERROR   ] [PID:1316807-TID:140204632602432] [language_ops.database:217] [FUNC:log_database_operation] DB_SELECT_FAILED: UserProfile for user 559773363 fields=['language'] - None
[2025-07-31 00:22:58.555] [ERROR   ] [PID:1316807-TID:140204632602432] [language_ops.database:217] [FUNC:log_database_operation] DB_SELECT_FAILED: UserProfile for user 559773363 fields=['language'] - None
[2025-07-31 00:22:59.351] [ERROR   ] [PID:1316807-TID:140204632602432] [language_ops.database:217] [FUNC:log_database_operation] DB_SELECT_FAILED: UserProfile for user 559773363 fields=['language'] - None
[2025-07-31 00:22:59.352] [ERROR   ] [PID:1316807-TID:140204632602432] [language_ops.database:217] [FUNC:log_database_operation] DB_UPDATE_FAILED: UserProfile for user 559773363 fields=['language'] - None
[2025-07-31 00:22:59.354] [ERROR   ] [PID:1316807-TID:140204236998400] [language_ops.database:217] [FUNC:log_database_operation] DB_GET_OR_CREATE_FAILED: UserProfile for user 559773363 fields=['telegram_id', 'language'] - None
[2025-07-31 00:22:59.357] [ERROR   ] [PID:1316807-TID:140204236998400] [language_ops.database:217] [FUNC:log_database_operation] DB_UPDATE_FAILED: UserProfile for user 559773363 fields=['language'] - None
[2025-07-31 01:00:47.528] [ERROR   ] [PID:1476174-TID:139830719899456] [language_ops.database:217] [FUNC:log_database_operation] DB_SELECT_FAILED: UserProfile for user 559773363 fields=['language'] - None
[2025-07-31 01:00:49.309] [ERROR   ] [PID:1476174-TID:139830719899456] [language_ops.database:217] [FUNC:log_database_operation] DB_SELECT_FAILED: UserProfile for user 559773363 fields=['language'] - None
[2025-07-31 01:00:50.770] [ERROR   ] [PID:1476174-TID:139830719899456] [language_ops.database:217] [FUNC:log_database_operation] DB_SELECT_FAILED: UserProfile for user 559773363 fields=['language'] - None
[2025-07-31 01:00:50.773] [ERROR   ] [PID:1476174-TID:139830719899456] [language_ops.database:217] [FUNC:log_database_operation] DB_UPDATE_FAILED: UserProfile for user 559773363 fields=['language'] - None
[2025-07-31 01:00:50.776] [ERROR   ] [PID:1476174-TID:139830392506112] [language_ops.database:217] [FUNC:log_database_operation] DB_GET_OR_CREATE_FAILED: UserProfile for user 559773363 fields=['telegram_id', 'language'] - None
[2025-07-31 01:00:50.779] [ERROR   ] [PID:1476174-TID:139830392506112] [language_ops.database:217] [FUNC:log_database_operation] DB_UPDATE_FAILED: UserProfile for user 559773363 fields=['language'] - None
[2025-07-31 01:02:01.642] [ERROR   ] [PID:1476174-TID:139830719899456] [language_ops.database:217] [FUNC:log_database_operation] DB_SELECT_FAILED: UserProfile for user 559773363 fields=['language'] - None
[2025-07-31 01:02:02.943] [ERROR   ] [PID:1476174-TID:139830719899456] [language_ops.database:217] [FUNC:log_database_operation] DB_SELECT_FAILED: UserProfile for user 559773363 fields=['language'] - None
[2025-07-31 01:02:02.945] [ERROR   ] [PID:1476174-TID:139830719899456] [language_ops.database:217] [FUNC:log_database_operation] DB_UPDATE_FAILED: UserProfile for user 559773363 fields=['language'] - None
[2025-07-31 01:02:02.947] [ERROR   ] [PID:1476174-TID:139830392506112] [language_ops.database:217] [FUNC:log_database_operation] DB_GET_OR_CREATE_FAILED: UserProfile for user 559773363 fields=['telegram_id', 'language'] - None
[2025-07-31 01:02:02.949] [ERROR   ] [PID:1476174-TID:139830392506112] [language_ops.database:217] [FUNC:log_database_operation] DB_UPDATE_FAILED: UserProfile for user 559773363 fields=['language'] - None
[2025-07-31 01:02:05.941] [ERROR   ] [PID:1476174-TID:139830719899456] [language_ops.database:217] [FUNC:log_database_operation] DB_SELECT_FAILED: UserProfile for user 559773363 fields=['language'] - None
[2025-07-31 01:02:07.084] [ERROR   ] [PID:1476174-TID:139830719899456] [language_ops.database:217] [FUNC:log_database_operation] DB_SELECT_FAILED: UserProfile for user 559773363 fields=['language'] - None
[2025-07-31 07:53:27.183] [ERROR   ] [PID:1476174-TID:139830719899456] [language_ops.database:217] [FUNC:log_database_operation] DB_SELECT_FAILED: UserProfile for user 559773363 fields=['language'] - None
[2025-07-31 07:53:28.315] [ERROR   ] [PID:1476174-TID:139830719899456] [language_ops.database:217] [FUNC:log_database_operation] DB_SELECT_FAILED: UserProfile for user 559773363 fields=['language'] - None
[2025-07-31 07:53:29.646] [ERROR   ] [PID:1476174-TID:139830719899456] [language_ops.database:217] [FUNC:log_database_operation] DB_SELECT_FAILED: UserProfile for user 559773363 fields=['language'] - None
[2025-07-31 07:53:29.649] [ERROR   ] [PID:1476174-TID:139830719899456] [language_ops.database:217] [FUNC:log_database_operation] DB_UPDATE_FAILED: UserProfile for user 559773363 fields=['language'] - None
[2025-07-31 07:53:29.651] [ERROR   ] [PID:1476174-TID:139830392506112] [language_ops.database:217] [FUNC:log_database_operation] DB_GET_OR_CREATE_FAILED: UserProfile for user 559773363 fields=['telegram_id', 'language'] - None
[2025-07-31 07:53:29.653] [ERROR   ] [PID:1476174-TID:139830392506112] [language_ops.database:217] [FUNC:log_database_operation] DB_UPDATE_FAILED: UserProfile for user 559773363 fields=['language'] - None
